<?xml version="1.0"?>
<robot name="humanoid_robot">
  <!-- Base link -->
  <link name="base_link">
    <inertial>
      <mass value="1.0" />
      <origin xyz="0 0 0"/>
      <inertia ixx="0.01" ixy="0.0" ixz="0.0" iyy="0.01" iyz="0.0" izz="0.01" />
    </inertial>
    <visual>
      <geometry>
        <box size="0.2 0.2 0.2" />
      </geometry>
      <material name="blue">
        <color rgba="0.0 0.0 1.0 1.0" />
      </material>
    </visual>
    <collision>
      <geometry>
        <box size="0.2 0.2 0.2" />
      </geometry>
    </collision>
  </link>

  <!-- Head link -->
  <link name="head">
    <inertial>
      <mass value="0.5" />
      <origin xyz="0 0 0"/>
      <inertia ixx="0.001" ixy="0.0" ixz="0.0" iyy="0.001" iyz="0.0" izz="0.001" />
    </inertial>
    <visual>
      <geometry>
        <sphere radius="0.1" />
      </geometry>
      <material name="red">
        <color rgba="1.0 0.0 0.0 1.0" />
      </material>
    </visual>
    <collision>
      <geometry>
        <sphere radius="0.1" />
      </geometry>
    </collision>
  </link>

  <!-- Joint connecting base to head -->
  <joint name="neck_joint" type="revolute">
    <parent link="base_link" />
    <child link="head" />
    <origin xyz="0 0 0.2" rpy="0 0 0" />
    <axis xyz="0 1 0" />
    <limit lower="-1.57" upper="1.57" effort="10.0" velocity="0.5" />
  </joint>

  <!-- Add more links and joints for complete humanoid robot -->
</robot>